Workbook

Sheet CONSOLIDADO
A1: Data | B1: Nome | C1: Modelo | D1: Pedido | E1: Valor | F1: Vendedor | G1: AGR | H1: Origem | I1: Nome_Separado | J1: CPF_CNPJ | K1: Parceiro | L1: Pedido_Numero | M1: Emissor | N1: Arquivo_Origem | O1: Data_Tratada | P1: Periodo | Q1: Ano | R1: Documento_Normalizado | S1: Tipo_Documento | T1: Valor_Numerico
A2: 01/04/2025 | B2: 25 275 940 Valeria Vieira Lima De Olivei CPF/CNPJ: 25.275.940/0001-14Parceiro: SEM INDICAÇÃO | C2: A1 - Software e-CNPJ de 12 Meses | D2: 1007750856 MYCERT | E2: R$ 180,00 | F2: Victor Alves De | G2: Victor Alves De | H2: Interno | I2: 25 275 940 Valeria Vieira Lima De Olivei | J2: 25.275.940/0001-14 | K2: SEM INDICAÇÃO | L2: 1007750856 | M2: MYCERT | N2: ABRIL 2025.xls | O2: 45748 | P2: 04/2025 | Q2: 2025 | R2: 25275940000114 | S2: CNPJ | T2: 180
A3: 01/04/2025 | B3: Decora Comercio De Tintas Ltda CPF/CNPJ: 26.645.587/0001-80Parceiro: SEM INDICAÇÃO | C3: A1 - Software e-CNPJ de 12 Meses | D3: 1007751431 MYCERT | E3: R$ 130,00 | F3: Danielle Olivei | G3: Danielle Olivei | H3: Interno | I3: Decora Comercio De Tintas Ltda | J3: 26.645.587/0001-80 | K3: SEM INDICAÇÃO | L3: 1007751431 | M3: MYCERT | N3: ABRIL 2025.xls | O3: 45748 | P3: 04/2025 | Q3: 2025 | R3: 26645587000180 | S3: CNPJ | T3: 130
A4: 01/04/2025 | B4: Associacao Dos Moradores Da Chacara 03 R CPF/CNPJ: 40.289.411/0001-63Parceiro: SUPORT CONDOMINIOS - Alexandre Silva | C4: A1 - Software e-CNPJ de 12 Meses | D4: 1007750892 MYCERT | E4: R$ 180,00 | F4: Suport Condomin | G4: Suport Condomin | H4: Parceiro | I4: Associacao Dos Moradores Da Chacara 03 R | J4: 40.289.411/0001-63 | K4: SUPORT CONDOMINIOS - Alexandre Silva | L4: 1007750892 | M4: MYCERT | N4: ABRIL 2025.xls | O4: 45748 | P4: 04/2025 | Q4: 2025 | R4: 40289411000163 | S4: CNPJ | T4: 180
A5: 01/04/2025 | B5: Planalto Central Imoveis Ltda CPF/CNPJ: 00.581.058/0001-76Parceiro: SOLUCOES CONTABEIS PERICIA E AUDITORIA LTDA | C5: A1 - Software e-CNPJ de 12 Meses | D5: 1007753642 MYCERT | E5: R$ 190,00 | F5: Raquel Campos D | G5: Raquel Campos D | H5: Interno | I5: Planalto Central Imoveis Ltda | J5: 00.581.058/0001-76 | K5: SOLUCOES CONTABEIS PERICIA E AUDITORIA LTDA | L5: 1007753642 | M5: MYCERT | N5: ABRIL 2025.xls | O5: 45748 | P5: 04/2025 | Q5: 2025 | R5: 00581058000176 | S5: CNPJ | T5: 190
A6: 01/04/2025 | B6: All Plast Embalagens Ltda CPF/CNPJ: 07.743.905/0001-09Parceiro: SEM INDICAÇÃO | C6: A1 - Software e-CNPJ de 12 Meses | D6: 1007753574 MYCERT | E6: R$ 180,00 | F6: Danielle Olivei | G6: Danielle Olivei | H6: Interno | I6: All Plast Embalagens Ltda | J6: 07.743.905/0001-09 | K6: SEM INDICAÇÃO | L6: 1007753574 | M6: MYCERT | N6: ABRIL 2025.xls | O6: 45748 | P6: 04/2025 | Q6: 2025 | R6: 07743905000109 | S6: CNPJ | T6: 180
A7: 01/04/2025 | B7: Sinn S Business Intelligence Ltda CPF/CNPJ: 60.144.555/0001-39Parceiro: SEM INDICAÇÃO | C7: A1 - Software e-CNPJ de 12 Meses | D7: 1007753562 MYCERT | E7: R$ 150,00 | F7: Leticia Mendon� | G7: Leticia Mendon� | H7: Interno | I7: Sinn S Business Intelligence Ltda | J7: 60.144.555/0001-39 | K7: SEM INDICAÇÃO | L7: 1007753562 | M7: MYCERT | N7: ABRIL 2025.xls | O7: 45748 | P7: 04/2025 | Q7: 2025 | R7: 60144555000139 | S7: CNPJ | T7: 150
A8: 01/04/2025 | B8: Delson Jose Da Silva CPF/CNPJ: 09.604.467/0001-15Parceiro: A TRIBUTÁRIA CONTABILIDADE | C8: A1 - Software e-CNPJ de 12 Meses | D8: 1007753905 MYCERT | E8: R$ 180,00 | F8: Raquel Campos D | G8: Raquel Campos D | H8: Interno | I8: Delson Jose Da Silva | J8: 09.604.467/0001-15 | K8: A TRIBUTÁRIA CONTABILIDADE | L8: 1007753905 | M8: MYCERT | N8: ABRIL 2025.xls | O8: 45748 | P8: 04/2025 | Q8: 2025 | R8: 09604467000115 | S8: CNPJ | T8: 180
A9: 01/04/2025 | B9: R7X Embalagens Comercio De Artigos De Us CPF/CNPJ: 36.620.239/0001-01Parceiro: SEM INDICAÇÃO | C9: A1 - Software e-CNPJ de 12 Meses | D9: 1007753663 MYCERT | E9: R$ 180,00 | F9: Danielle Olivei | G9: Danielle Olivei | H9: Interno | I9: R7X Embalagens Comercio De Artigos De Us | J9: 36.620.239/0001-01 | K9: SEM INDICAÇÃO | L9: 1007753663 | M9: MYCERT | N9: ABRIL 2025.xls | O9: 45748 | P9: 04/2025 | Q9: 2025 | R9: 36620239000101 | S9: CNPJ | T9: 180
A10: 01/04/2025 | B10: Condominio Do Bloco E Da Scln Quadra 306 CPF/CNPJ: 73.323.669/0001-98Parceiro: SEM INDICAÇÃO | C10: A1 - Software e-CNPJ de 12 Meses | D10: 1007753970 MYCERT | E10: R$ 150,00 | F10: Leticia Mendon� | G10: Leticia Mendon� | H10: Interno | I10: Condominio Do Bloco E Da Scln Quadra 306 | J10: 73.323.669/0001-98 | K10: SEM INDICAÇÃO | L10: 1007753970 | M10: MYCERT | N10: ABRIL 2025.xls | O10: 45748 | P10: 04/2025 | Q10: 2025 | R10: 73323669000198 | S10: CNPJ | T10: 150
A11: 01/04/2025 | B11: Mailine Chaveiro Brasilia Ltda CPF/CNPJ: 50.133.144/0001-94Parceiro: SEM INDICAÇÃO | C11: A1 - Software e-CNPJ de 12 Meses | D11: 1007754085 MYCERT | E11: R$ 180,00 | F11: Danielle Olivei | G11: Danielle Olivei | H11: Interno | I11: Mailine Chaveiro Brasilia Ltda | J11: 50.133.144/0001-94 | K11: SEM INDICAÇÃO | L11: 1007754085 | M11: MYCERT | N11: ABRIL 2025.xls | O11: 45748 | P11: 04/2025 | Q11: 2025 | R11: 50133144000194 | S11: CNPJ | T11: 180
A12: 01/04/2025 | B12: Luiz Carlos Penteado De Luca CPF/CNPJ: 065.967.278-23Parceiro: SEM INDICAÇÃO | C12: A1 - Software e-CPF de 12 Meses | D12: 1007621108 MYCERT | E12: R$ 130,00 | F12: Victor Alves De | G12: Victor Alves De | H12: Interno | I12: Luiz Carlos Penteado De Luca | J12: 065.967.278-23 | K12: SEM INDICAÇÃO | L12: 1007621108 | M12: MYCERT | N12: ABRIL 2025.xls | O12: 45748 | P12: 04/2025 | Q12: 2025 | R12: 06596727823 | S12: CPF | T12: 130
A13: 01/04/2025 | B13: Waltonei Da Costa Pinto Ltda CPF/CNPJ: 72.600.877/0001-24Parceiro: SEM INDICAÇÃO | C13: A1 - Software e-CNPJ de 12 Meses | D13: 1007754543 MYCERT | E13: R$ 154,00 | F13: Karina Pereira | G13: Karina Pereira | H13: Interno | I13: Waltonei Da Costa Pinto Ltda | J13: 72.600.877/0001-24 | K13: SEM INDICAÇÃO | L13: 1007754543 | M13: MYCERT | N13: ABRIL 2025.xls | O13: 45748 | P13: 04/2025 | Q13: 2025 | R13: 72600877000124 | S13: CNPJ | T13: 154
... A6302: 21/05/2025 | B6302: Katia Bianca De Jesus 34318909115 CPF/CNPJ: 17.997.505/0001-75Parceiro: SEM INDICAÇÃO | C6302: A1 - Software e-CNPJ de 12 Meses | D6302: 1008075099 MYCERT | E6302: R$ 150,00 | F6302: Leticia Mendon� | G6302: Leticia Mendon� | H6302: Interno | I6302: Katia Bianca De Jesus 34318909115 | J6302: 17.997.505/0001-75 | K6302: SEM INDICAÇÃO | L6302: 1008075099 | M6302: MYCERT | N6302: MAIO 2025.xls | O6302: 45798 | P6302: 05/2025 | Q6302: 2025 | R6302: 17997505000175 | S6302: CNPJ | T6302: 150
A6303: 21/05/2025 | B6303: Condominio Da Chacara 41 Da Colonia Agri CPF/CNPJ: 05.739.916/0001-81Parceiro: | C6303: A1 - Software e-CNPJ de 12 Meses | D6303: 1008077642 MYCERT | E6303: R$ 72,00 | F6303: Renata Kelle De | G6303: Renata Kelle De | H6303: Interno | I6303: Condominio Da Chacara 41 Da Colonia Agri | J6303: 05.739.916/0001-81 | L6303: 1008077642 | M6303: MYCERT | N6303: MAIO 2025.xls | O6303: 45798 | P6303: 05/2025 | Q6303: 2025 | R6303: 05739916000181 | S6303: CNPJ | T6303: 72
A6304: 21/05/2025 | B6304: Drogas Mil Ltda CPF/CNPJ: 41.480.326/0001-40Parceiro: SEM INDICAÇÃO | C6304: A1 - Software e-CNPJ de 12 Meses | D6304: 1008077994 MYCERT | E6304: R$ 165,00 | F6304: Danielle Olivei | G6304: Danielle Olivei | H6304: Interno | I6304: Drogas Mil Ltda | J6304: 41.480.326/0001-40 | K6304: SEM INDICAÇÃO | L6304: 1008077994 | M6304: MYCERT | N6304: MAIO 2025.xls | O6304: 45798 | P6304: 05/2025 | Q6304: 2025 | R6304: 41480326000140 | S6304: CNPJ | T6304: 165
A6305: 21/05/2025 | B6305: 52 558 994 Francisco Raimundo Freires Se CPF/CNPJ: 52.558.994/0001-60Parceiro: SEM INDICAÇÃO | C6305: A1 - Software e-CNPJ de 12 Meses | D6305: 1008079481 MYCERT | E6305: R$ 180,00 | F6305: Raquel Campos D | G6305: Raquel Campos D | H6305: Interno | I6305: 52 558 994 Francisco Raimundo Freires Se | J6305: 52.558.994/0001-60 | K6305: SEM INDICAÇÃO | L6305: 1008079481 | M6305: MYCERT | N6305: MAIO 2025.xls | O6305: 45798 | P6305: 05/2025 | Q6305: 2025 | R6305: 52558994000160 | S6305: CNPJ | T6305: 180
A6306: 21/05/2025 | B6306: Rosa Maria Bezerra Das Neves 20662220544 CPF/CNPJ: 23.495.605/0001-04Parceiro: SEM INDICAÇÃO | C6306: A1 - Software e-CNPJ de 12 Meses | D6306: 1008079838 MYCERT | E6306: R$ 180,00 | F6306: Raquel Campos D | G6306: Raquel Campos D | H6306: Interno | I6306: Rosa Maria Bezerra Das Neves 20662220544 | J6306: 23.495.605/0001-04 | K6306: SEM INDICAÇÃO | L6306: 1008079838 | M6306: MYCERT | N6306: MAIO 2025.xls | O6306: 45798 | P6306: 05/2025 | Q6306: 2025 | R6306: 23495605000104 | S6306: CNPJ | T6306: 180
A6307: 21/05/2025 | B6307: Reila Monique Cenci CPF/CNPJ: 009.670.571-08Parceiro: SEM INDICAÇÃO | C6307: A1 - Software e-CPF de 12 Meses | D6307: 1007984488 MYCERT | E6307: R$ 150,00 | F6307: Danielle Olivei | G6307: Danielle Olivei | H6307: Interno | I6307: Reila Monique Cenci | J6307: 009.670.571-08 | K6307: SEM INDICAÇÃO | L6307: 1007984488 | M6307: MYCERT | N6307: MAIO 2025.xls | O6307: 45798 | P6307: 05/2025 | Q6307: 2025 | R6307: 00967057108 | S6307: CPF | T6307: 150
A6308: 21/05/2025 | B6308: Daniel Avelino Gomes CPF/CNPJ: 19.548.339/0001-55Parceiro: GEOVANI GONCALVES DA ROSA | C6308: A1 - Software e-CNPJ de 12 Meses | D6308: 1008080811 MYCERT | E6308: R$ 160,00 | F6308: Danielle Olivei | G6308: Danielle Olivei | H6308: Interno | I6308: Daniel Avelino Gomes | J6308: 19.548.339/0001-55 | K6308: GEOVANI GONCALVES DA ROSA | L6308: 1008080811 | M6308: MYCERT | N6308: MAIO 2025.xls | O6308: 45798 | P6308: 05/2025 | Q6308: 2025 | R6308: 19548339000155 | S6308: CNPJ | T6308: 160
A6309: 21/05/2025 | B6309: Direcao Produtos Automotivos Ltda CPF/CNPJ: 08.184.963/0001-02Parceiro: VIRTUAL CONTABILIDADE E CONSULTORIA S/S LTDA | C6309: A1 - Software e-CNPJ de 12 Meses | D6309: 1008079847 MYCERT | E6309: R$ 180,00 | F6309: Karina Pereira | G6309: Karina Pereira | H6309: Interno | I6309: Direcao Produtos Automotivos Ltda | J6309: 08.184.963/0001-02 | K6309: VIRTUAL CONTABILIDADE E CONSULTORIA S/S LTDA | L6309: 1008079847 | M6309: MYCERT | N6309: MAIO 2025.xls | O6309: 45798 | P6309: 05/2025 | Q6309: 2025 | R6309: 08184963000102 | S6309: CNPJ | T6309: 180
A6310: 21/05/2025 | B6310: Laura De Oliveira Vieira CPF/CNPJ: 567.843.921-91Parceiro: LEVVO INSTITUTO | C6310: A1 - Software e-CPF de 12 Meses | D6310: 1008067127 MYCERT | E6310: R$ 150,00 | F6310: Karina Pereira | G6310: Karina Pereira | H6310: Interno | I6310: Laura De Oliveira Vieira | J6310: 567.843.921-91 | K6310: LEVVO INSTITUTO | L6310: 1008067127 | M6310: MYCERT | N6310: MAIO 2025.xls | O6310: 45798 | P6310: 05/2025 | Q6310: 2025 | R6310: 56784392191 | S6310: CPF | T6310: 150
A6311: 21/05/2025 | B6311: Pedro Vinicius Ferreira Coelho CPF/CNPJ: 027.614.981-51Parceiro: SEM INDICAÇÃO | C6311: A1 - Software e-CPF de 12 Meses | D6311: 1008081699 MYCERT | E6311: R$ 130,00 | F6311: Danielle Olivei | G6311: Danielle Olivei | H6311: Interno | I6311: Pedro Vinicius Ferreira Coelho | J6311: 027.614.981-51 | K6311: SEM INDICAÇÃO | L6311: 1008081699 | M6311: MYCERT | N6311: MAIO 2025.xls | O6311: 45798 | P6311: 05/2025 | Q6311: 2025 | R6311: 02761498151 | S6311: CPF | T6311: 130
A6312: 21/05/2025 | B6312: Jdb Confeccoes Ltda CPF/CNPJ: 60.317.629/0001-91Parceiro: LEVVO INSTITUTO | C6312: A1 - Software e-CNPJ de 12 Meses | D6312: 1008067011 MYCERT | E6312: R$ 200,00 | F6312: Karina Pereira | G6312: Karina Pereira | H6312: Interno | I6312: Jdb Confeccoes Ltda | J6312: 60.317.629/0001-91 | K6312: LEVVO INSTITUTO | L6312: 1008067011 | M6312: MYCERT | N6312: MAIO 2025.xls | O6312: 45798 | P6312: 05/2025 | Q6312: 2025 | R6312: 60317629000191 | S6312: CNPJ | T6312: 200
A6313: 21/05/2025 | B6313: Lve Construcoes E Energia Ltda CPF/CNPJ: 60.317.624/0001-69Parceiro: LEVVO INSTITUTO | C6313: A1 - Software e-CNPJ de 12 Meses | D6313: 1008067056 MYCERT | E6313: R$ 200,00 | F6313: Karina Pereira | G6313: Karina Pereira | H6313: Interno | I6313: Lve Construcoes E Energia Ltda | J6313: 60.317.624/0001-69 | K6313: LEVVO INSTITUTO | L6313: 1008067056 | M6313: MYCERT | N6313: MAIO 2025.xls | O6313: 45798 | P6313: 05/2025 | Q6313: 2025 | R6313: 60317624000169 | S6313: CNPJ | T6313: 200
A6314: 21/05/2025 | B6314: Levvo Df Comercio De Alimentos Ltda CPF/CNPJ: 02.749.926/0001-00Parceiro: LEVVO INSTITUTO | C6314: A1 - Software e-CNPJ de 12 Meses | D6314: 1008067173 MYCERT | E6314: R$ 200,00 | F6314: Karina Pereira | G6314: Karina Pereira | H6314: Interno | I6314: Levvo Df Comercio De Alimentos Ltda | J6314: 02.749.926/0001-00 | K6314: LEVVO INSTITUTO | L6314: 1008067173 | M6314: MYCERT | N6314: MAIO 2025.xls | O6314: 45798 | P6314: 05/2025 | Q6314: 2025 | R6314: 02749926000100 | S6314: CNPJ | T6314: 200
A6315: 21/05/2025 | B6315: Levvo Comercio De Alimentos Ltda CPF/CNPJ: 12.647.271/0001-12Parceiro: LEVVO INSTITUTO | C6315: A1 - Software e-CNPJ de 12 Meses | D6315: 1008067193 MYCERT | E6315: R$ 200,00 | F6315: Karina Pereira | G6315: Karina Pereira | H6315: Interno | I6315: Levvo Comercio De Alimentos Ltda | J6315: 12.647.271/0001-12 | K6315: LEVVO INSTITUTO | L6315: 1008067193 | M6315: MYCERT | N6315: MAIO 2025.xls | O6315: 45798 | P6315: 05/2025 | Q6315: 2025 | R6315: 12647271000112 | S6315: CNPJ | T6315: 200
... A6317: 21/05/2025 | B6317: Joao Pereira De Santana CPF/CNPJ: 870.137.205-00Parceiro: IBAMA | C6317: A3 - Nuvem SafeID e-CPF de 12 Meses | D6317: 1008079188 MYCERT | E6317: R$ 100,00 | F6317: Karina Pereira | G6317: Karina Pereira | H6317: Interno | I6317: Joao Pereira De Santana | J6317: 870.137.205-00 | K6317: IBAMA | L6317: 1008079188 | M6317: MYCERT | N6317: MAIO 2025.xls | O6317: 45798 | P6317: 05/2025 | Q6317: 2025 | R6317: 87013720500 | S6317: CPF | T6317: 100
A6318: 21/05/2025 | B6318: Joao Pereira De Santana CPF/CNPJ: 870.137.205-00Parceiro: | C6318: A3 - Nuvem SafeID e-CPF de 12 Meses | D6318: 1008079188 MYCERT | E6318: R$ 100,00 | F6318: Victor Alves De | G6318: Victor Alves De | H6318: Interno | I6318: Joao Pereira De Santana | J6318: 870.137.205-00 | L6318: 1008079188 | M6318: MYCERT | N6318: MAIO 2025.xls | O6318: 45798 | P6318: 05/2025 | Q6318: 2025 | R6318: 87013720500 | S6318: CPF | T6318: 100
A6319: 21/05/2025 | B6319: Celso Brambilla CPF/CNPJ: 008.602.548-10Parceiro: ONLINE ASSESSORIA CONTABIL LTDA | C6319: A1 - Software e-CPF de 12 Meses | D6319: 1008081620 MYCERT | E6319: R$ 130,00 | F6319: Leticia Mendon� | G6319: Leticia Mendon� | H6319: Interno | I6319: Celso Brambilla | J6319: 008.602.548-10 | K6319: ONLINE ASSESSORIA CONTABIL LTDA | L6319: 1008081620 | M6319: MYCERT | N6319: MAIO 2025.xls | O6319: 45798 | P6319: 05/2025 | Q6319: 2025 | R6319: 00860254810 | S6319: CPF | T6319: 130
A6320: 21/05/2025 | B6320: Pricila Luisa Santos Silva Ltda CPF/CNPJ: 19.366.957/0001-84Parceiro: SEM INDICAÇÃO | C6320: A1 - Software e-CNPJ de 12 Meses | D6320: 1008082647 MYCERT | E6320: R$ 190,00 | F6320: Raquel Campos D | G6320: Raquel Campos D | H6320: Interno | I6320: Pricila Luisa Santos Silva Ltda | J6320: 19.366.957/0001-84 | K6320: SEM INDICAÇÃO | L6320: 1008082647 | M6320: MYCERT | N6320: MAIO 2025.xls | O6320: 45798 | P6320: 05/2025 | Q6320: 2025 | R6320: 19366957000184 | S6320: CNPJ | T6320: 190
A6321: 21/05/2025 | B6321: Condominio Do Edificio Residencial Atena CPF/CNPJ: 33.525.445/0001-44Parceiro: SEM INDICAÇÃO | C6321: A1 - Software e-CNPJ de 12 Meses | D6321: 1008072068 MYCERT | E6321: R$ 200,00 | F6321: Raquel Campos D | G6321: Raquel Campos D | H6321: Interno | I6321: Condominio Do Edificio Residencial Atena | J6321: 33.525.445/0001-44 | K6321: SEM INDICAÇÃO | L6321: 1008072068 | M6321: MYCERT | N6321: MAIO 2025.xls | O6321: 45798 | P6321: 05/2025 | Q6321: 2025 | R6321: 33525445000144 | S6321: CNPJ | T6321: 200
A6322: 22/05/2025 | B6322: Moreira Ramos Administradora De Bens E D CPF/CNPJ: 30.354.793/0001-08Parceiro: SEM INDICAÇÃO | C6322: A1 - Software e-CNPJ de 12 Meses | D6322: 1008080797 MYCERT | E6322: R$ 190,00 | F6322: Karina Pereira | G6322: Karina Pereira | H6322: Interno | I6322: Moreira Ramos Administradora De Bens E D | J6322: 30.354.793/0001-08 | K6322: SEM INDICAÇÃO | L6322: 1008080797 | M6322: MYCERT | N6322: MAIO 2025.xls | O6322: 45799 | P6322: 05/2025 | Q6322: 2025 | R6322: 30354793000108 | S6322: CNPJ | T6322: 190
A6323: 22/05/2025 | B6323: Dev To Go Desenvolvimento De Software Lt CPF/CNPJ: 30.794.711/0001-46Parceiro: SEM INDICAÇÃO | C6323: A1 - Software e-CNPJ de 12 Meses | D6323: 1008084475 MYCERT | E6323: R$ 180,00 | F6323: Leticia Mendon� | G6323: Leticia Mendon� | H6323: Interno | I6323: Dev To Go Desenvolvimento De Software Lt | J6323: 30.794.711/0001-46 | K6323: SEM INDICAÇÃO | L6323: 1008084475 | M6323: MYCERT | N6323: MAIO 2025.xls | O6323: 45799 | P6323: 05/2025 | Q6323: 2025 | R6323: 30794711000146 | S6323: CNPJ | T6323: 180
A6324: 22/05/2025 | B6324: Menegatti Comercial Atacadista Ltda CPF/CNPJ: 01.794.337/0001-80Parceiro: GOOGLE | C6324: A1 - Software e-CNPJ de 12 Meses | D6324: 1008084951 MYCERT | E6324: R$ 180,00 | F6324: Raquel Campos D | G6324: Raquel Campos D | H6324: Interno | I6324: Menegatti Comercial Atacadista Ltda | J6324: 01.794.337/0001-80 | K6324: GOOGLE | L6324: 1008084951 | M6324: MYCERT | N6324: MAIO 2025.xls | O6324: 45799 | P6324: 05/2025 | Q6324: 2025 | R6324: 01794337000180 | S6324: CNPJ | T6324: 180
A6325: 22/05/2025 | B6325: Marcio Pessoa Soares De Lima CPF/CNPJ: 821.345.961-04Parceiro: M T CONSULTORIA E ASSESSORIA CONTABIL LTDA | C6325: A1 - Software e-CPF de 12 Meses | D6325: 1008084176 MYCERT | E6325: R$ 0,00 | F6325: Leticia Mendon� | G6325: Leticia Mendon� | H6325: Interno | I6325: Marcio Pessoa Soares De Lima | J6325: 821.345.961-04 | K6325: M T CONSULTORIA E ASSESSORIA CONTABIL LTDA | L6325: 1008084176 | M6325: MYCERT | N6325: MAIO 2025.xls | O6325: 45799 | P6325: 05/2025 | Q6325: 2025 | R6325: 82134596104 | S6325: CPF | T6325: 0
A6326: 22/05/2025 | B6326: M T Consultoria E Assessoria Contabil Lt CPF/CNPJ: 41.911.545/0001-37Parceiro: M T CONSULTORIA E ASSESSORIA CONTABIL LTDA | C6326: A1 - Software e-CNPJ de 12 Meses | D6326: 1008084209 MYCERT | E6326: R$ 0,00 | F6326: Leticia Mendon� | G6326: Leticia Mendon� | H6326: Interno | I6326: M T Consultoria E Assessoria Contabil Lt | J6326: 41.911.545/0001-37 | K6326: M T CONSULTORIA E ASSESSORIA CONTABIL LTDA | L6326: 1008084209 | M6326: MYCERT | N6326: MAIO 2025.xls | O6326: 45799 | P6326: 05/2025 | Q6326: 2025 | R6326: 41911545000137 | S6326: CNPJ | T6326: 0
A6327: 22/05/2025 | B6327: Aguas Lindas Vistorias Veiculares Ltda CPF/CNPJ: 60.525.880/0001-41Parceiro: SEM INDICAÇÃO | C6327: A1 - Software e-CNPJ de 12 Meses | D6327: 1008077980 MYCERT | E6327: R$ 139,00 | F6327: Raquel Campos D | G6327: Raquel Campos D | H6327: Interno | I6327: Aguas Lindas Vistorias Veiculares Ltda | J6327: 60.525.880/0001-41 | K6327: SEM INDICAÇÃO | L6327: 1008077980 | M6327: MYCERT | N6327: MAIO 2025.xls | O6327: 45799 | P6327: 05/2025 | Q6327: 2025 | R6327: 60525880000141 | S6327: CNPJ | T6327: 139
A6328: 22/05/2025 | B6328: Petcetera Produtos Veterinarios Ltda CPF/CNPJ: 07.546.038/0001-03Parceiro: ONLINE ASSESSORIA CONTABIL LTDA | C6328: A1 - Software e-CNPJ de 12 Meses | D6328: 1008085525 MYCERT | E6328: R$ 180,00 | F6328: Raquel Campos D | G6328: Raquel Campos D | H6328: Interno | I6328: Petcetera Produtos Veterinarios Ltda | J6328: 07.546.038/0001-03 | K6328: ONLINE ASSESSORIA CONTABIL LTDA | L6328: 1008085525 | M6328: MYCERT | N6328: MAIO 2025.xls | O6328: 45799 | P6328: 05/2025 | Q6328: 2025 | R6328: 07546038000103 | S6328: CNPJ | T6328: 180
A6329: 22/05/2025 | B6329: Constantina Cafe E Quitutes Ltda CPF/CNPJ: 42.343.858/0001-07Parceiro: SEM INDICAÇÃO | C6329: A1 - Software e-CNPJ de 12 Meses | D6329: 1008083779 MYCERT | E6329: R$ 190,00 | F6329: Leticia Mendon� | G6329: Leticia Mendon� | H6329: Interno | I6329: Constantina Cafe E Quitutes Ltda | J6329: 42.343.858/0001-07 | K6329: SEM INDICAÇÃO | L6329: 1008083779 | M6329: MYCERT | N6329: MAIO 2025.xls | O6329: 45799 | P6329: 05/2025 | Q6329: 2025 | R6329: 42343858000107 | S6329: CNPJ | T6329: 190
...

Sheet LISTA RENOVACAO
A1: Documento_Normalizado | B1: CPF_CNPJ | C1: Tipo_Documento | D1: Nome_Separado | E1: Ultima_Data_2025 | F1: Qtd_Certificados_2025 | G1: Valor_Total_2025 | H1: Ultimo_Modelo_2025 | I1: Ultimo_Vendedor_2025 | J1: Status_Renovacao
A2: 00012352306 | B2: 000.123.523-06 | C2: CPF | D2: Francisco Dos Santos Silva | E2: 45908 | F2: 1 | G2: 150 | H2: A1 - Software e-CPF de 12 Meses | I2: Leticia Mendon� | J2: NAO RENOVOU EM 2026
A3: 00022355367 | B3: 000.223.553-67 | C3: CPF | D3: Deborah Kelly Guimaraes Cardoso | E3: 45796 | F3: 1 | G3: 137 | H3: A1 - Software e-CPF de 12 Meses | I3: Eni Assessoria | J3: NAO RENOVOU EM 2026
A4: 00028392108 | B4: 000.283.921-08 | C4: CPF | D4: Edney Siqueira De Oliveira | E4: 45832 | F4: 1 | G4: 240 | H4: A3 - S/ Mídia e-CPF de 36 Meses | I4: Victor Alves De | J4: NAO RENOVOU EM 2026
A5: 00034656162 | B5: 000.346.561-62 | C5: CPF | D5: Jackeline Da Silva Andrade | E5: 45831 | F5: 1 | G5: 150 | H5: A1 - Software e-CPF de 12 Meses | I5: Victor Alves De | J5: NAO RENOVOU EM 2026
A6: 00041904168 | B6: 000.419.041-68 | C6: CPF | D6: Oraida Policena De Andrade Campos | E6: 45852 | F6: 1 | G6: 150 | H6: A1 - Software e-CPF de 12 Meses | I6: Victor Alves De | J6: NAO RENOVOU EM 2026
A7: 00044321000198 | B7: 00.044.321/0001-98 | C7: CNPJ | D7: Afonso M Moreno E Silva | E7: 45779 | F7: 1 | G7: 180 | H7: A1 - Software e-PJ de 12 Meses | I7: Raquel Campos D | J7: NAO RENOVOU EM 2026
A8: 00046526145 | B8: 000.465.261-45 | C8: CPF | D8: Silvia Leticia Vale | E8: 45741 | F8: 1 | G8: 130 | H8: A1 - Software e-CPF de 12 Meses | I8: Karina Pereira | J8: NAO RENOVOU EM 2026
A9: 00049247115 | B9: 000.492.471-15 | C9: CPF | D9: Oswaldo Bastos Braga | E9: 45833 | F9: 1 | G9: 130 | H9: A1 - Software e-CPF de 12 Meses | I9: Raquel Campos D | J9: NAO RENOVOU EM 2026
A10: 00065536134 | B10: 000.655.361-34 | C10: CPF | D10: Joao Candido Da Silva | E10: 45980 | F10: 1 | G10: 110 | H10: A1 - Software e-CPF de 12 Meses | I10: Raquel Campos D | J10: NAO RENOVOU EM 2026
A11: 00074197000103 | B11: 00.074.197/0001-03 | C11: CNPJ | D11: Caperon Incorporacoes Ltda | E11: 45812 | F11: 1 | G11: 149.9 | H11: A1 - Software e-CNPJ de 12 Meses | I11: Karina Pereira | J11: NAO RENOVOU EM 2026
A12: 00078801117 | B12: 000.788.011-17 | C12: CPF | D12: Fernanda Pinheiro Pinto | E12: 45882 | F12: 1 | G12: 0 | H12: A1 - Software e-CPF de 12 Meses | I12: Danielle Olivei | J12: NAO RENOVOU EM 2026
A13: 00089377000169 | B13: 00.089.377/0001-69 | C13: CNPJ | D13: Posto Julio De Castilho Limitada | E13: 45835 | F13: 1 | G13: 760 | H13: A1 - Software e-CNPJ de 12 Meses | I13: Leticia Mendon� | J13: NAO RENOVOU EM 2026
... A5098: 99841924315 | B5098: 998.419.243-15 | C5098: CPF | D5098: Marcos Romano Nascimento De Oliveira | E5098: 45891 | F5098: 1 | G5098: 150 | H5098: A1 - Software e-CPF de 12 Meses | I5098: Leticia Mendon� | J5098: NAO RENOVOU EM 2026

Sheet INDICADORES COMERCIAIS
A1: INDICADORES COMERCIAIS
A3: Filtro lateral
A4: Periodo | B4: 05/2026
A6: Indicador | B6: Resultado | D6: Origem | E6: Quantidade | G6: Vendedor | H6: Quantidade no periodo | J6: Modelo | K6: Quantidade no periodo
A7: Total de certificados | B7: =COUNTIF(CONSOLIDADO!$P:$P,$B$4) | D7: Interno | E7: =COUNTIFS(CONSOLIDADO!$P:$P,$B$4,CONSOLIDADO!$H:$H,D7) | G7: Raquel Campos D | H7: =COUNTIFS(CONSOLIDADO!$P:$P,$B$4,CONSOLIDADO!$F:$F,G7) | J7: A1 - Software e-CNPJ de 12 Meses | K7: =COUNTIFS(CONSOLIDADO!$P:$P,$B$4,CONSOLIDADO!$C:$C,J7)
A8: Valor total | B8: =SUMIF(CONSOLIDADO!$P:$P,$B$4,CONSOLIDADO!$T:$T) | D8: Parceiro | E8: =COUNTIFS(CONSOLIDADO!$P:$P,$B$4,CONSOLIDADO!$H:$H,D8) | G8: Karina Pereira | H8: =COUNTIFS(CONSOLIDADO!$P:$P,$B$4,CONSOLIDADO!$F:$F,G8) | J8: A1 - Software e-CPF de 12 Meses | K8: =COUNTIFS(CONSOLIDADO!$P:$P,$B$4,CONSOLIDADO!$C:$C,J8)
A9: Ticket medio | B9: =IFERROR(B8/B7,0) | G9: Danielle Olivei | H9: =COUNTIFS(CONSOLIDADO!$P:$P,$B$4,CONSOLIDADO!$F:$F,G9) | J9: A1 - Software e-PJ de 12 Meses | K9: =COUNTIFS(CONSOLIDADO!$P:$P,$B$4,CONSOLIDADO!$C:$C,J9)
A10: Clientes unicos | B10: =COUNTA(UNIQUE(FILTER(CONSOLIDADO!$R:$R,(CONSOLIDADO!$P:$P=$B$4)*(CONSOLIDADO!$R:$R<>"")))) | G10: Victor Alves De | H10: =COUNTIFS(CONSOLIDADO!$P:$P,$B$4,CONSOLIDADO!$F:$F,G10) | J10: A3 - Nuvem SafeID e-CPF de 12 Meses | K10: =COUNTIFS(CONSOLIDADO!$P:$P,$B$4,CONSOLIDADO!$C:$C,J10)
A11: Certificados CPF | B11: =COUNTIFS(CONSOLIDADO!$P:$P,$B$4,CONSOLIDADO!$S:$S,"CPF") | G11: Leticia Mendon� | H11: =COUNTIFS(CONSOLIDADO!$P:$P,$B$4,CONSOLIDADO!$F:$F,G11) | J11: A3 - Token e-CPF de 36 Meses | K11: =COUNTIFS(CONSOLIDADO!$P:$P,$B$4,CONSOLIDADO!$C:$C,J11)
A12: Certificados CNPJ | B12: =COUNTIFS(CONSOLIDADO!$P:$P,$B$4,CONSOLIDADO!$S:$S,"CNPJ") | G12: Vila21 Condomin | H12: =COUNTIFS(CONSOLIDADO!$P:$P,$B$4,CONSOLIDADO!$F:$F,G12) | J12: A3 - Nuvem SafeID e-CPF de 36 Meses | K12: =COUNTIFS(CONSOLIDADO!$P:$P,$B$4,CONSOLIDADO!$C:$C,J12)
G13: Joyce Nathally | H13: =COUNTIFS(CONSOLIDADO!$P:$P,$B$4,CONSOLIDADO!$F:$F,G13) | J13: A3 - Token e-CNPJ de 36 Meses | K13: =COUNTIFS(CONSOLIDADO!$P:$P,$B$4,CONSOLIDADO!$C:$C,J13)
G14: Seven Stars Ser | H14: =COUNTIFS(CONSOLIDADO!$P:$P,$B$4,CONSOLIDADO!$F:$F,G14) | J14: A3 - S/ Mídia e-CPF de 36 Meses | K14: =COUNTIFS(CONSOLIDADO!$P:$P,$B$4,CONSOLIDADO!$C:$C,J14)
A15: Ao alterar o periodo em B4, os indicadores desta aba sao recalculados no Excel. | G15: Barucci Contabi | H15: =COUNTIFS(CONSOLIDADO!$P:$P,$B$4,CONSOLIDADO!$F:$F,G15) | J15: A3 - Token e-CPF de 24 Meses | K15: =COUNTIFS(CONSOLIDADO!$P:$P,$B$4,CONSOLIDADO!$C:$C,J15)
G16: Adipron Servico | H16: =COUNTIFS(CONSOLIDADO!$P:$P,$B$4,CONSOLIDADO!$F:$F,G16) | J16: A3 - S/ Mídia e-CNPJ de 36 Meses | K16: =COUNTIFS(CONSOLIDADO!$P:$P,$B$4,CONSOLIDADO!$C:$C,J16)
G17: Giga Comercial | H17: =COUNTIFS(CONSOLIDADO!$P:$P,$B$4,CONSOLIDADO!$F:$F,G17) | J17: A3 - S/ Mídia e-CPF de 24 Meses | K17: =COUNTIFS(CONSOLIDADO!$P:$P,$B$4,CONSOLIDADO!$C:$C,J17)
G18: Suport Condomin | H18: =COUNTIFS(CONSOLIDADO!$P:$P,$B$4,CONSOLIDADO!$F:$F,G18) | J18: A3 - Nuvem SafeID e-CPF de 24 Meses | K18: =COUNTIFS(CONSOLIDADO!$P:$P,$B$4,CONSOLIDADO!$C:$C,J18)
G19: Eni Assessoria | H19: =COUNTIFS(CONSOLIDADO!$P:$P,$B$4,CONSOLIDADO!$F:$F,G19) | J19: A3 - S/ Mídia e-CPF de 12 Meses | K19: =COUNTIFS(CONSOLIDADO!$P:$P,$B$4,CONSOLIDADO!$C:$C,J19)
G20: Anderson Lisboa | H20: =COUNTIFS(CONSOLIDADO!$P:$P,$B$4,CONSOLIDADO!$F:$F,G20) | J20: A3 - S/ Mídia e-CNPJ de 24 Meses | K20: =COUNTIFS(CONSOLIDADO!$P:$P,$B$4,CONSOLIDADO!$C:$C,J20)
G21: Fabio Lucas Oli | H21: =COUNTIFS(CONSOLIDADO!$P:$P,$B$4,CONSOLIDADO!$F:$F,G21) | J21: A3 - Token e-CNPJ de 24 Meses | K21: =COUNTIFS(CONSOLIDADO!$P:$P,$B$4,CONSOLIDADO!$C:$C,J21)
G22: Renata Kelle De | H22: =COUNTIFS(CONSOLIDADO!$P:$P,$B$4,CONSOLIDADO!$F:$F,G22) | J22: A3 - Cartão e-CNPJ de 36 Meses | K22: =COUNTIFS(CONSOLIDADO!$P:$P,$B$4,CONSOLIDADO!$C:$C,J22)
G23: Confit Intelige | H23: =COUNTIFS(CONSOLIDADO!$P:$P,$B$4,CONSOLIDADO!$F:$F,G23) | J23: A3 - Token e-CPF de 12 Meses | K23: =COUNTIFS(CONSOLIDADO!$P:$P,$B$4,CONSOLIDADO!$C:$C,J23)
G24: Giovanna Maria | H24: =COUNTIFS(CONSOLIDADO!$P:$P,$B$4,CONSOLIDADO!$F:$F,G24) | J24: A3 - Nuvem SafeID e-CPF de 4 Meses | K24: =COUNTIFS(CONSOLIDADO!$P:$P,$B$4,CONSOLIDADO!$C:$C,J24)
G25: Solucoes Admini | H25: =COUNTIFS(CONSOLIDADO!$P:$P,$B$4,CONSOLIDADO!$F:$F,G25) | J25: A3 - Cartão e-CPF de 36 Meses | K25: =COUNTIFS(CONSOLIDADO!$P:$P,$B$4,CONSOLIDADO!$C:$C,J25)
G26: 64.846.726 Cint | H26: =COUNTIFS(CONSOLIDADO!$P:$P,$B$4,CONSOLIDADO!$F:$F,G26) | J26: A3 - Cartão e-CNPJ de 12 Meses | K26: =COUNTIFS(CONSOLIDADO!$P:$P,$B$4,CONSOLIDADO!$C:$C,J26)

Sheet AUX_PERIODOS
A1: Periodos
A2: 01/2025
A3: 02/2025
A4: 03/2025
A5: 04/2025
A6: 05/2025
A7: 06/2025
A8: 07/2025
A9: 08/2025
A10: 09/2025
A11: 10/2025
A12: 11/2025
... A18: 05/2026
